Workbook

Sheet Raw Data
A1: Date | B1: Batch ID | C1: Shift | D1: Line | E1: Product | F1: Planned Qty (kg) | G1: Produced Qty (kg) | H1: Rejected Qty (kg) | I1: Planned Time (min) | J1: Downtime (min) | K1: Ideal Rate (kg/min) | L1: Raw Material Input (kg) | M1: Energy (kWh) | N1: Labor Hours | O1: Raw Material Cost ($/kg) | P1: Downtime Reason | Q1: Micro Test
A2: 46204 | B2: B260701-0001 | C2: A | D2: Bakery | E2: Bread | F2: 3802 | G2: 3693 | H2: 88 | I2: 480 | J2: 15 | K2: 9 | L2: 3848 | M2: 1792 | N2: 48 | O2: 1.02 | P2: Changeover | Q2: Pass
A3: 46204 | B3: B260701-0002 | C3: B | D3: Dairy | E3: Cheese | F3: 1690 | G3: 1567 | H3: 30 | I3: 480 | J3: 26 | K3: 4 | L3: 1632 | M3: 870 | N3: 48 | O3: 4.52 | P3: Cleaning / CIP | Q3: Pass
A4: 46204 | B4: B260701-0003 | C4: C | D4: Beverage | E4: Juice | F4: 8448 | G4: 8070 | H4: 181 | I4: 480 | J4: 0 | K4: 20 | L4: 8413 | M4: 1172 | N4: 48 | O4: 0.73 | P4: None | Q4: Pass
A5: 46204 | B5: B260701-0004 | C5: A | D5: Frozen | E5: Frozen Pizza | F5: 2112 | G5: 2182 | H5: 83 | I5: 480 | J5: 18 | K5: 5 | L5: 2281 | M5: 1255 | N5: 48 | O5: 3.01 | P5: Changeover | Q5: Pass
A6: 46205 | B6: B260702-0005 | C6: B | D6: Bakery | E6: Cookies | F6: 2534 | G6: 2434 | H6: 94 | I6: 480 | J6: 40 | K6: 6 | L6: 2530 | M6: 1520 | N6: 48 | O6: 2.04 | P6: Quality hold | Q6: Pass
A7: 46205 | B7: B260702-0006 | C7: C | D7: Dairy | E7: Yogurt | F7: 5069 | G7: 4713 | H7: 93 | I7: 480 | J7: 18 | K7: 12 | L7: 4906 | M7: 1376 | N7: 48 | O7: 1.29 | P7: Changeover | Q7: Pass
A8: 46205 | B8: B260702-0007 | C8: A | D8: Beverage | E8: Soda | F8: 10560 | G8: 8680 | H8: 64 | I8: 480 | J8: 103 | K8: 25 | L8: 9055 | M8: 971 | N8: 48 | O8: 0.4 | P8: Cleaning / CIP | Q8: Pass
A9: 46205 | B9: B260702-0008 | C9: B | D9: Frozen | E9: Ice Cream | F9: 3379 | G9: 3316 | H9: 121 | I9: 480 | J9: 41 | K9: 8 | L9: 3418 | M9: 2104 | N9: 48 | O9: 2.27 | P9: Cleaning / CIP | Q9: Pass
A10: 46206 | B10: B260703-0009 | C10: C | D10: Bakery | E10: Bread | F10: 3802 | G10: 2933 | H10: 79 | I10: 480 | J10: 106 | K10: 9 | L10: 3035 | M10: 1429 | N10: 48 | O10: 1.05 | P10: Quality hold | Q10: Pass
A11: 46206 | B11: B260703-0010 | C11: A | D11: Dairy | E11: Cheese | F11: 1690 | G11: 1576 | H11: 52 | I11: 480 | J11: 51 | K11: 4 | L11: 1631 | M11: 818 | N11: 48 | O11: 4.74 | P11: Changeover | Q11: Pass
A12: 46206 | B12: B260703-0011 | C12: B | D12: Beverage | E12: Juice | F12: 8448 | G12: 8563 | H12: 158 | I12: 480 | J12: 16 | K12: 20 | L12: 8867 | M12: 1172 | N12: 48 | O12: 0.74 | P12: Changeover | Q12: Pass
A13: 46206 | B13: B260703-0012 | C13: C | D13: Frozen | E13: Frozen Pizza | F13: 2112 | G13: 1480 | H13: 73 | I13: 480 | J13: 128 | K13: 5 | L13: 1542 | M13: 820 | N13: 48 | O13: 2.96 | P13: Quality hold | Q13: Pass
... A369: 46295 | B369: B260930-0368 | C369: B | D369: Frozen | E369: Ice Cream | F369: 3379 | G369: 3315 | H369: 94 | I369: 480 | J369: 30 | K369: 8 | L369: 3421 | M369: 2263 | N369: 48 | O369: 2.45 | P369: Equipment failure | Q369: Pass

Sheet Calculations
A1: Food Production – Calculations
A2: All figures are formulas on 'Raw Data' (rows 2-1000). To use your own data: paste it into 'Raw Data' from row 2 in the same column order. Blue cells on yellow below are editable assumptions.
A4: ASSUMPTIONS & TARGETS
A5: OEE target | B5: 0.85 | C5: Typical world-class OEE benchmark (assumption)
A6: Reject rate limit | B6: 0.03 | C6: Assumption – maximum acceptable reject %
A7: Micro-test fail limit | B7: 0.01 | C7: Assumption – maximum acceptable fail rate
A8: Gross margin target | B8: 0.3 | C8: Assumption
A9: Energy cost ($/kWh) | B9: 0.12 | C9: Assumption – replace with tariff
A10: Labor cost ($/hour) | B10: 18 | C10: Assumption – replace with loaded labor rate
A12: PRODUCT MASTER (selling price)
A13: Product | B13: Line | C13: Selling Price ($/kg)
A14: Bread | B14: Bakery | C14: 2.8
A15: Cookies | B15: Bakery | C15: 5.5
A16: Yogurt | B16: Dairy | C16: 3.2
A17: Cheese | B17: Dairy | C17: 9.5
A18: Juice | B18: Beverage | C18: 1.9
A19: Soda | B19: Beverage | C19: 1.2
A20: Ice Cream | B20: Frozen | C20: 6
A21: Frozen Pizza | B21: Frozen | C21: 7
A22: Selling prices are illustrative assumptions (blue/yellow = editable).
A23: LINE KPIs
A24: Line | B24: Batches | C24: Planned (kg) | D24: Produced (kg) | E24: Rejected (kg) | F24: Good (kg) | G24: Reject % | H24: Planned Time (min) | I24: Downtime (min) | J24: Ideal Output (kg) | K24: Availability | L24: Performance | M24: Quality | N24: OEE | O24: Raw Material Input (kg) | P24: Energy (kWh) | Q24: kWh / kg good | R24: Labor Hours | S24: Revenue ($) | T24: Material Cost ($) | U24: Energy Cost ($) | V24: Labor Cost ($) | W24: Total Cost ($) | X24: Gross Margin ($) | Y24: Margin % | Z24: Cost / kg good ($) | AA24: Micro Fails | AB24: Micro Fail % | AC24: OEE Target
A25: Bakery | B25: =COUNTIFS('Raw Data'!$D$2:$D$1000,$A25) -> 92 | C25: =SUMIFS('Raw Data'!$F$2:$F$1000,'Raw Data'!$D$2:$D$1000,$A25) -> 291456 | D25: =SUMIFS('Raw Data'!$G$2:$G$1000,'Raw Data'!$D$2:$D$1000,$A25) -> 269661 | E25: =SUMIFS('Raw Data'!$H$2:$H$1000,'Raw Data'!$D$2:$D$1000,$A25) -> 7029 | F25: =D25-E25 -> 262632 | G25: =IFERROR(E25/D25,0) -> 0.026066061 | H25: =SUMIFS('Raw Data'!$I$2:$I$1000,'Raw Data'!$D$2:$D$1000,$A25) -> 44160 | I25: =SUMIFS('Raw Data'!$J$2:$J$1000,'Raw Data'!$D$2:$D$1000,$A25) -> 4181 | J25: =SUMPRODUCT(('Raw Data'!$D$2:$D$1000=$A25)*('Raw Data'!$I$2:$I$1000-'Raw Data'!$J$2:$J$1000)*'Raw Data'!$K$2:$K$1000) -> 298839 | K25: =IFERROR((H25-I25)/H25,0) -> 0.90532156 | L25: =IFERROR(D25/J25,0) -> 0.90236214 | M25: =IFERROR(F25/D25,0) -> 0.97393394 | N25: =K25*L25*M25 -> 0.79563381 | O25: =SUMIFS('Raw Data'!$L$2:$L$1000,'Raw Data'!$D$2:$D$1000,$A25) -> 279948 | P25: =SUMIFS('Raw Data'!$M$2:$M$1000,'Raw Data'!$D$2:$D$1000,$A25) -> 137860 | Q25: =IFERROR(P25/F25,0) -> 0.52491699 | R25: =SUMIFS('Raw Data'!$N$2:$N$1000,'Raw Data'!$D$2:$D$1000,$A25) -> 4416 | S25: =SUMIFS($J$33:$J$40,$B$33:$B$40,$A25) -> 1022698.2 | T25: =SUMIFS($K$33:$K$40,$B$33:$B$40,$A25) -> 426560.04 | U25: =P25*$B$9 -> 16543.2 | V25: =R25*$B$10 -> 79488 | W25: =T25+U25+V25 -> 522591.24 | X25: =S25-W25 -> 500106.96 | Y25: =IFERROR(X25/S25,0) -> 0.48900737 | Z25: =IFERROR(W25/F25,0) -> 1.9898232 | AA25: =COUNTIFS('Raw Data'!$D$2:$D$1000,$A25,'Raw Data'!$Q$2:$Q$1000,"Fail") -> 0 | AB25: =IFERROR(AA25/B25,0) -> 0 | AC25: =$B$5 -> 0.85
A26: Dairy | B26: =COUNTIFS('Raw Data'!$D$2:$D$1000,$A26) -> 92 | C26: =SUMIFS('Raw Data'!$F$2:$F$1000,'Raw Data'!$D$2:$D$1000,$A26) -> 310914 | D26: =SUMIFS('Raw Data'!$G$2:$G$1000,'Raw Data'!$D$2:$D$1000,$A26) -> 291511 | E26: =SUMIFS('Raw Data'!$H$2:$H$1000,'Raw Data'!$D$2:$D$1000,$A26) -> 6732 | F26: =D26-E26 -> 284779 | G26: =IFERROR(E26/D26,0) -> 0.023093468 | H26: =SUMIFS('Raw Data'!$I$2:$I$1000,'Raw Data'!$D$2:$D$1000,$A26) -> 44160 | I26: =SUMIFS('Raw Data'!$J$2:$J$1000,'Raw Data'!$D$2:$D$1000,$A26) -> 3765 | J26: =SUMPRODUCT(('Raw Data'!$D$2:$D$1000=$A26)*('Raw Data'!$I$2:$I$1000-'Raw Data'!$J$2:$J$1000)*'Raw Data'!$K$2:$K$1000) -> 322356 | K26: =IFERROR((H26-I26)/H26,0) -> 0.91474185 | L26: =IFERROR(D26/J26,0) -> 0.90431386 | M26: =IFERROR(F26/D26,0) -> 0.97690653 | N26: =K26*L26*M26 -> 0.8081105 | O26: =SUMIFS('Raw Data'!$L$2:$L$1000,'Raw Data'!$D$2:$D$1000,$A26) -> 302470 | P26: =SUMIFS('Raw Data'!$M$2:$M$1000,'Raw Data'!$D$2:$D$1000,$A26) -> 104428 | Q26: =IFERROR(P26/F26,0) -> 0.36669839 | R26: =SUMIFS('Raw Data'!$N$2:$N$1000,'Raw Data'!$D$2:$D$1000,$A26) -> 4416 | S26: =SUMIFS($J$33:$J$40,$B$33:$B$40,$A26) -> 1360974.2 | T26: =SUMIFS($K$33:$K$40,$B$33:$B$40,$A26) -> 662525.55 | U26: =P26*$B$9 -> 12531.36 | V26: =R26*$B$10 -> 79488 | W26: =T26+U26+V26 -> 754544.91 | X26: =S26-W26 -> 606429.29 | Y26: =IFERROR(X26/S26,0) -> 0.44558471 | Z26: =IFERROR(W26/F26,0) -> 2.6495806 | AA26: =COUNTIFS('Raw Data'!$D$2:$D$1000,$A26,'Raw Data'!$Q$2:$Q$1000,"Fail") -> 1 | AB26: =IFERROR(AA26/B26,0) -> 0.010869565 | AC26: =$B$5 -> 0.85
A27: Beverage | B27: =COUNTIFS('Raw Data'!$D$2:$D$1000,$A27) -> 92 | C27: =SUMIFS('Raw Data'!$F$2:$F$1000,'Raw Data'!$D$2:$D$1000,$A27) -> 874368 | D27: =SUMIFS('Raw Data'!$G$2:$G$1000,'Raw Data'!$D$2:$D$1000,$A27) -> 830866 | E27: =SUMIFS('Raw Data'!$H$2:$H$1000,'Raw Data'!$D$2:$D$1000,$A27) -> 11080 | F27: =D27-E27 -> 819786 | G27: =IFERROR(E27/D27,0) -> 0.013335484 | H27: =SUMIFS('Raw Data'!$I$2:$I$1000,'Raw Data'!$D$2:$D$1000,$A27) -> 44160 | I27: =SUMIFS('Raw Data'!$J$2:$J$1000,'Raw Data'!$D$2:$D$1000,$A27) -> 3361 | J27: =SUMPRODUCT(('Raw Data'!$D$2:$D$1000=$A27)*('Raw Data'!$I$2:$I$1000-'Raw Data'!$J$2:$J$1000)*'Raw Data'!$K$2:$K$1000) -> 919010 | K27: =IFERROR((H27-I27)/H27,0) -> 0.9238904 | L27: =IFERROR(D27/J27,0) -> 0.90408809 | M27: =IFERROR(F27/D27,0) -> 0.98666452 | N27: =K27*L27*M27 -> 0.82413947 | O27: =SUMIFS('Raw Data'!$L$2:$L$1000,'Raw Data'!$D$2:$D$1000,$A27) -> 861747 | P27: =SUMIFS('Raw Data'!$M$2:$M$1000,'Raw Data'!$D$2:$D$1000,$A27) -> 109673 | Q27: =IFERROR(P27/F27,0) -> 0.13378247 | R27: =SUMIFS('Raw Data'!$N$2:$N$1000,'Raw Data'!$D$2:$D$1000,$A27) -> 4416 | S27: =SUMIFS($J$33:$J$40,$B$33:$B$40,$A27) -> 1235058.6 | T27: =SUMIFS($K$33:$K$40,$B$33:$B$40,$A27) -> 491022.96 | U27: =P27*$B$9 -> 13160.76 | V27: =R27*$B$10 -> 79488 | W27: =T27+U27+V27 -> 583671.72 | X27: =S27-W27 -> 651386.88 | Y27: =IFERROR(X27/S27,0) -> 0.52741374 | Z27: =IFERROR(W27/F27,0) -> 0.71198059 | AA27: =COUNTIFS('Raw Data'!$D$2:$D$1000,$A27,'Raw Data'!$Q$2:$Q$1000,"Fail") -> 1 | AB27: =IFERROR(AA27/B27,0) -> 0.010869565 | AC27: =$B$5 -> 0.85
A28: Frozen | B28: =COUNTIFS('Raw Data'!$D$2:$D$1000,$A28) -> 92 | C28: =SUMIFS('Raw Data'!$F$2:$F$1000,'Raw Data'!$D$2:$D$1000,$A28) -> 252586 | D28: =SUMIFS('Raw Data'!$G$2:$G$1000,'Raw Data'!$D$2:$D$1000,$A28) -> 243957 | E28: =SUMIFS('Raw Data'!$H$2:$H$1000,'Raw Data'!$D$2:$D$1000,$A28) -> 9488 | F28: =D28-E28 -> 234469 | G28: =IFERROR(E28/D28,0) -> 0.0388921 | H28: =SUMIFS('Raw Data'!$I$2:$I$1000,'Raw Data'!$D$2:$D$1000,$A28) -> 44160 | I28: =SUMIFS('Raw Data'!$J$2:$J$1000,'Raw Data'!$D$2:$D$1000,$A28) -> 2826 | J28: =SUMPRODUCT(('Raw Data'!$D$2:$D$1000=$A28)*('Raw Data'!$I$2:$I$1000-'Raw Data'!$J$2:$J$1000)*'Raw Data'!$K$2:$K$1000) -> 269349 | K28: =IFERROR((H28-I28)/H28,0) -> 0.93600543 | L28: =IFERROR(D28/J28,0) -> 0.90572826 | M28: =IFERROR(F28/D28,0) -> 0.9611079 | N28: =K28*L28*M28 -> 0.81479515 | O28: =SUMIFS('Raw Data'!$L$2:$L$1000,'Raw Data'!$D$2:$D$1000,$A28) -> 253469 | P28: =SUMIFS('Raw Data'!$M$2:$M$1000,'Raw Data'!$D$2:$D$1000,$A28) -> 157629 | Q28: =IFERROR(P28/F28,0) -> 0.67228077 | R28: =SUMIFS('Raw Data'!$N$2:$N$1000,'Raw Data'!$D$2:$D$1000,$A28) -> 4416 | S28: =SUMIFS($J$33:$J$40,$B$33:$B$40,$A28) -> 1495531 | T28: =SUMIFS($K$33:$K$40,$B$33:$B$40,$A28) -> 671747.45 | U28: =P28*$B$9 -> 18915.48 | V28: =R28*$B$10 -> 79488 | W28: =T28+U28+V28 -> 770150.93 | X28: =S28-W28 -> 725380.07 | Y28: =IFERROR(X28/S28,0) -> 0.48503178 | Z28: =IFERROR(W28/F28,0) -> 3.2846599 | AA28: =COUNTIFS('Raw Data'!$D$2:$D$1000,$A28,'Raw Data'!$Q$2:$Q$1000,"Fail") -> 0 | AB28: =IFERROR(AA28/B28,0) -> 0 | AC28: =$B$5 -> 0.85
A29: Total | B29: =SUM(B25:B28) -> 368 | C29: =SUM(C25:C28) -> 1729324 | D29: =SUM(D25:D28) -> 1635995 | E29: =SUM(E25:E28) -> 34329 | F29: =SUM(F25:F28) -> 1601666 | G29: =IFERROR(E29/D29,0) -> 0.02098356 | H29: =SUM(H25:H28) -> 176640 | I29: =SUM(I25:I28) -> 14133 | J29: =SUM(J25:J28) -> 1809554 | K29: =IFERROR((H29-I29)/H29,0) -> 0.91998981 | L29: =IFERROR(D29/J29,0) -> 0.90408742 | M29: =IFERROR(F29/D29,0) -> 0.97901644 | N29: =K29*L29*M29 -> 0.81429811 | O29: =SUM(O25:O28) -> 1697634 | P29: =SUM(P25:P28) -> 509590 | Q29: =IFERROR(P29/F29,0) -> 0.31816246 | R29: =SUM(R25:R28) -> 17664 | S29: =SUM(S25:S28) -> 5114262 | T29: =SUM(T25:T28) -> 2251856 | U29: =SUM(U25:U28) -> 61150.8 | V29: =SUM(V25:V28) -> 317952 | W29: =SUM(W25:W28) -> 2630958.8 | X29: =SUM(X25:X28) -> 2483303.2 | Y29: =IFERROR(X29/S29,0) -> 0.48556433 | Z29: =IFERROR(W29/F29,0) -> 1.6426389 | AA29: =SUM(AA25:AA28) -> 2 | AB29: =IFERROR(AA29/B29,0) -> 0.0054347826
A31: PRODUCT KPIs
A32: Product | B32: Line | C32: Batches | D32: Produced (kg) | E32: Rejected (kg) | F32: Good (kg) | G32: Reject % | H32: Raw Material Input (kg) | I32: Price ($/kg) | J32: Revenue ($) | K32: Material Cost ($) | L32: Energy Cost ($) | M32: Labor Cost ($) | N32: Total Cost ($) | O32: Gross Margin ($) | P32: Margin % | Q32: Cost / kg good ($)
A33: =A14 -> Bread | B33: =B14 -> Bakery | C33: =COUNTIFS('Raw Data'!$E$2:$E$1000,$A33) -> 46 | D33: =SUMIFS('Raw Data'!$G$2:$G$1000,'Raw Data'!$E$2:$E$1000,$A33) -> 159648 | E33: =SUMIFS('Raw Data'!$H$2:$H$1000,'Raw Data'!$E$2:$E$1000,$A33) -> 3434 | F33: =D33-E33 -> 156214 | G33: =IFERROR(E33/D33,0) -> 0.021509822 | H33: =SUMIFS('Raw Data'!$L$2:$L$1000,'Raw Data'!$E$2:$E$1000,$A33) -> 165939 | I33: =C14 -> 2.8 | J33: =F33*I33 -> 437399.2 | K33: =SUMPRODUCT(('Raw Data'!$E$2:$E$1000=$A33)*'Raw Data'!$L$2:$L$1000*'Raw Data'!$O$2:$O$1000) -> 179452.67 | L33: =SUMIFS('Raw Data'!$M$2:$M$1000,'Raw Data'!$E$2:$E$1000,$A33)*$B$9 -> 8656.08 | M33: =SUMIFS('Raw Data'!$N$2:$N$1000,'Raw Data'!$E$2:$E$1000,$A33)*$B$10 -> 39744 | N33: =K33+L33+M33 -> 227852.75 | O33: =J33-N33 -> 209546.45 | P33: =IFERROR(O33/J33,0) -> 0.47907369 | Q33: =IFERROR(N33/F33,0) -> 1.4585937
A34: =A15 -> Cookies | B34: =B15 -> Bakery | C34: =COUNTIFS('Raw Data'!$E$2:$E$1000,$A34) -> 46 | D34: =SUMIFS('Raw Data'!$G$2:$G$1000,'Raw Data'!$E$2:$E$1000,$A34) -> 110013 | E34: =SUMIFS('Raw Data'!$H$2:$H$1000,'Raw Data'!$E$2:$E$1000,$A34) -> 3595 | F34: =D34-E34 -> 106418 | G34: =IFERROR(E34/D34,0) -> 0.032677956 | H34: =SUMIFS('Raw Data'!$L$2:$L$1000,'Raw Data'!$E$2:$E$1000,$A34) -> 114009 | I34: =C15 -> 5.5 | J34: =F34*I34 -> 585299 | K34: =SUMPRODUCT(('Raw Data'!$E$2:$E$1000=$A34)*'Raw Data'!$L$2:$L$1000*'Raw Data'!$O$2:$O$1000) -> 247107.37 | L34: =SUMIFS('Raw Data'!$M$2:$M$1000,'Raw Data'!$E$2:$E$1000,$A34)*$B$9 -> 7887.12 | M34: =SUMIFS('Raw Data'!$N$2:$N$1000,'Raw Data'!$E$2:$E$1000,$A34)*$B$10 -> 39744 | N34: =K34+L34+M34 -> 294738.49 | O34: =J34-N34 -> 290560.51 | P34: =IFERROR(O34/J34,0) -> 0.4964309 | Q34: =IFERROR(N34/F34,0) -> 2.76963
A35: =A16 -> Yogurt | B35: =B16 -> Dairy | C35: =COUNTIFS('Raw Data'!$E$2:$E$1000,$A35) -> 46 | D35: =SUMIFS('Raw Data'!$G$2:$G$1000,'Raw Data'!$E$2:$E$1000,$A35) -> 218157 | E35: =SUMIFS('Raw Data'!$H$2:$H$1000,'Raw Data'!$E$2:$E$1000,$A35) -> 4756 | F35: =D35-E35 -> 213401 | G35: =IFERROR(E35/D35,0) -> 0.021800813 | H35: =SUMIFS('Raw Data'!$L$2:$L$1000,'Raw Data'!$E$2:$E$1000,$A35) -> 226252 | I35: =C16 -> 3.2 | J35: =F35*I35 -> 682883.2 | K35: =SUMPRODUCT(('Raw Data'!$E$2:$E$1000=$A35)*'Raw Data'!$L$2:$L$1000*'Raw Data'!$O$2:$O$1000) -> 302315.37 | L35: =SUMIFS('Raw Data'!$M$2:$M$1000,'Raw Data'!$E$2:$E$1000,$A35)*$B$9 -> 7715.28 | M35: =SUMIFS('Raw Data'!$N$2:$N$1000,'Raw Data'!$E$2:$E$1000,$A35)*$B$10 -> 39744 | N35: =K35+L35+M35 -> 349774.65 | O35: =J35-N35 -> 333108.55 | P35: =IFERROR(O35/J35,0) -> 0.48779725 | Q35: =IFERROR(N35/F35,0) -> 1.6390488
A36: =A17 -> Cheese | B36: =B17 -> Dairy | C36: =COUNTIFS('Raw Data'!$E$2:$E$1000,$A36) -> 46 | D36: =SUMIFS('Raw Data'!$G$2:$G$1000,'Raw Data'!$E$2:$E$1000,$A36) -> 73354 | E36: =SUMIFS('Raw Data'!$H$2:$H$1000,'Raw Data'!$E$2:$E$1000,$A36) -> 1976 | F36: =D36-E36 -> 71378 | G36: =IFERROR(E36/D36,0) -> 0.026937863 | H36: =SUMIFS('Raw Data'!$L$2:$L$1000,'Raw Data'!$E$2:$E$1000,$A36) -> 76218 | I36: =C17 -> 9.5 | J36: =F36*I36 -> 678091 | K36: =SUMPRODUCT(('Raw Data'!$E$2:$E$1000=$A36)*'Raw Data'!$L$2:$L$1000*'Raw Data'!$O$2:$O$1000) -> 360210.18 | L36: =SUMIFS('Raw Data'!$M$2:$M$1000,'Raw Data'!$E$2:$E$1000,$A36)*$B$9 -> 4816.08 | M36: =SUMIFS('Raw Data'!$N$2:$N$1000,'Raw Data'!$E$2:$E$1000,$A36)*$B$10 -> 39744 | N36: =K36+L36+M36 -> 404770.26 | O36: =J36-N36 -> 273320.74 | P36: =IFERROR(O36/J36,0) -> 0.40307384 | Q36: =IFERROR(N36/F36,0) -> 5.6707986
A37: =A18 -> Juice | B37: =B18 -> Beverage | C37: =COUNTIFS('Raw Data'!$E$2:$E$1000,$A37) -> 46 | D37: =SUMIFS('Raw Data'!$G$2:$G$1000,'Raw Data'!$E$2:$E$1000,$A37) -> 365059 | E37: =SUMIFS('Raw Data'!$H$2:$H$1000,'Raw Data'!$E$2:$E$1000,$A37) -> 6037 | F37: =D37-E37 -> 359022 | G37: =IFERROR(E37/D37,0) -> 0.016537053 | H37: =SUMIFS('Raw Data'!$L$2:$L$1000,'Raw Data'!$E$2:$E$1000,$A37) -> 378818 | I37: =C18 -> 1.9 | J37: =F37*I37 -> 682141.8 | K37: =SUMPRODUCT(('Raw Data'!$E$2:$E$1000=$A37)*'Raw Data'!$L$2:$L$1000*'Raw Data'!$O$2:$O$1000) -> 292153.19 | L37: =SUMIFS('Raw Data'!$M$2:$M$1000,'Raw Data'!$E$2:$E$1000,$A37)*$B$9 -> 6574.32 | M37: =SUMIFS('Raw Data'!$N$2:$N$1000,'Raw Data'!$E$2:$E$1000,$A37)*$B$10 -> 39744 | N37: =K37+L37+M37 -> 338471.51 | O37: =J37-N37 -> 343670.29 | P37: =IFERROR(O37/J37,0) -> 0.50381063 | Q37: =IFERROR(N37/F37,0) -> 0.9427598
A38: =A19 -> Soda | B38: =B19 -> Beverage | C38: =COUNTIFS('Raw Data'!$E$2:$E$1000,$A38) -> 46 | D38: =SUMIFS('Raw Data'!$G$2:$G$1000,'Raw Data'!$E$2:$E$1000,$A38) -> 465807 | E38: =SUMIFS('Raw Data'!$H$2:$H$1000,'Raw Data'!$E$2:$E$1000,$A38) -> 5043 | F38: =D38-E38 -> 460764 | G38: =IFERROR(E38/D38,0) -> 0.010826372 | H38: =SUMIFS('Raw Data'!$L$2:$L$1000,'Raw Data'!$E$2:$E$1000,$A38) -> 482929 | I38: =C19 -> 1.2 | J38: =F38*I38 -> 552916.8 | K38: =SUMPRODUCT(('Raw Data'!$E$2:$E$1000=$A38)*'Raw Data'!$L$2:$L$1000*'Raw Data'!$O$2:$O$1000) -> 198869.77 | L38: =SUMIFS('Raw Data'!$M$2:$M$1000,'Raw Data'!$E$2:$E$1000,$A38)*$B$9 -> 6586.44 | M38: =SUMIFS('Raw Data'!$N$2:$N$1000,'Raw Data'!$E$2:$E$1000,$A38)*$B$10 -> 39744 | N38: =K38+L38+M38 -> 245200.21 | O38: =J38-N38 -> 307716.59 | P38: =IFERROR(O38/J38,0) -> 0.55653326 | Q38: =IFERROR(N38/F38,0) -> 0.53216009
A39: =A20 -> Ice Cream | B39: =B20 -> Frozen | C39: =COUNTIFS('Raw Data'!$E$2:$E$1000,$A39) -> 46 | D39: =SUMIFS('Raw Data'!$G$2:$G$1000,'Raw Data'!$E$2:$E$1000,$A39) -> 151086 | E39: =SUMIFS('Raw Data'!$H$2:$H$1000,'Raw Data'!$E$2:$E$1000,$A39) -> 5334 | F39: =D39-E39 -> 145752 | G39: =IFERROR(E39/D39,0) -> 0.035304396 | H39: =SUMIFS('Raw Data'!$L$2:$L$1000,'Raw Data'!$E$2:$E$1000,$A39) -> 156916 | I39: =C20 -> 6 | J39: =F39*I39 -> 874512 | K39: =SUMPRODUCT(('Raw Data'!$E$2:$E$1000=$A39)*'Raw Data'!$L$2:$L$1000*'Raw Data'!$O$2:$O$1000) -> 373150.92 | L39: =SUMIFS('Raw Data'!$M$2:$M$1000,'Raw Data'!$E$2:$E$1000,$A39)*$B$9 -> 12715.32 | M39: =SUMIFS('Raw Data'!$N$2:$N$1000,'Raw Data'!$E$2:$E$1000,$A39)*$B$10 -> 39744 | N39: =K39+L39+M39 -> 425610.24 | O39: =J39-N39 -> 448901.76 | P39: =IFERROR(O39/J39,0) -> 0.51331687 | Q39: =IFERROR(N39/F39,0) -> 2.9200988
A40: =A21 -> Frozen Pizza | B40: =B21 -> Frozen | C40: =COUNTIFS('Raw Data'!$E$2:$E$1000,$A40) -> 46 | D40: =SUMIFS('Raw Data'!$G$2:$G$1000,'Raw Data'!$E$2:$E$1000,$A40) -> 92871 | E40: =SUMIFS('Raw Data'!$H$2:$H$1000,'Raw Data'!$E$2:$E$1000,$A40) -> 4154 | F40: =D40-E40 -> 88717 | G40: =IFERROR(E40/D40,0) -> 0.04472871 | H40: =SUMIFS('Raw Data'!$L$2:$L$1000,'Raw Data'!$E$2:$E$1000,$A40) -> 96553 | I40: =C21 -> 7 | J40: =F40*I40 -> 621019 | K40: =SUMPRODUCT(('Raw Data'!$E$2:$E$1000=$A40)*'Raw Data'!$L$2:$L$1000*'Raw Data'!$O$2:$O$1000) -> 298596.53 | L40: =SUMIFS('Raw Data'!$M$2:$M$1000,'Raw Data'!$E$2:$E$1000,$A40)*$B$9 -> 6200.16 | M40: =SUMIFS('Raw Data'!$N$2:$N$1000,'Raw Data'!$E$2:$E$1000,$A40)*$B$10 -> 39744 | N40: =K40+L40+M40 -> 344540.69 | O40: =J40-N40 -> 276478.31 | P40: =IFERROR(O40/J40,0) -> 0.44520105 | Q40: =IFERROR(N40/F40,0) -> 3.8835927
A43: MONTHLY KPIs
A44: Month (start) | B44: Batches | C44: Produced (kg) | D44: Rejected (kg) | E44: Good (kg) | F44: Reject % | G44: Planned Time (min) | H44: Downtime (min) | I44: Ideal Output (kg) | J44: Availability | K44: Performance | L44: Quality | M44: OEE | N44: Raw Material Input (kg) | O44: Revenue ($) | P44: Total Cost ($) | Q44: Gross Margin ($) | R44: Margin % | S44: Label | T44: OEE Target
A45: 46204 | B45: =COUNTIFS('Raw Data'!$A$2:$A$1000,">="&$A45,'Raw Data'!$A$2:$A$1000,"<"&EDATE($A45,1)) -> 124 | C45: =SUMIFS('Raw Data'!$G$2:$G$1000,'Raw Data'!$A$2:$A$1000,">="&$A45,'Raw Data'!$A$2:$A$1000,"<"&EDATE($A45,1)) -> 549596 | D45: =SUMIFS('Raw Data'!$H$2:$H$1000,'Raw Data'!$A$2:$A$1000,">="&$A45,'Raw Data'!$A$2:$A$1000,"<"&EDATE($A45,1)) -> 11219 | E45: =C45-D45 -> 538377 | F45: =IFERROR(D45/C45,0) -> 0.020413176 | G45: =SUMIFS('Raw Data'!$I$2:$I$1000,'Raw Data'!$A$2:$A$1000,">="&$A45,'Raw Data'!$A$2:$A$1000,"<"&EDATE($A45,1)) -> 59520 | H45: =SUMIFS('Raw Data'!$J$2:$J$1000,'Raw Data'!$A$2:$A$1000,">="&$A45,'Raw Data'!$A$2:$A$1000,"<"&EDATE($A45,1)) -> 4581 | I45: =SUMPRODUCT(('Raw Data'!$A$2:$A$1000>=$A45)*('Raw Data'!$A$2:$A$1000<EDATE($A45,1))*('Raw Data'!$I$2:$I$1000-'Raw Data'!$J$2:$J$1000)*'Raw Data'!$K$2:$K$1000) -> 609558 | J45: =IFERROR((G45-H45)/G45,0) -> 0.92303427 | K45: =IFERROR(C45/I45,0) -> 0.90163036 | L45: =IFERROR(E45/C45,0) -> 0.97958682 | M45: =J45*K45*L45 -> 0.81524715 | N45: =SUMIFS('Raw Data'!$L$2:$L$1000,'Raw Data'!$A$2:$A$1000,">="&$A45,'Raw Data'!$A$2:$A$1000,"<"&EDATE($A45,1)) -> 570880 | O45: =SUMPRODUCT(('Raw Data'!$A$2:$A$1000>=$A45)*('Raw Data'!$A$2:$A$1000<EDATE($A45,1))*('Raw Data'!$G$2:$G$1000-'Raw Data'!$H$2:$H$1000)*SUMIF($A$14:$A$21,'Raw Data'!$E$2:$E$1000,$C$14:$C$21)) -> 1727237.4 | P45: =SUMPRODUCT(('Raw Data'!$A$2:$A$1000>=$A45)*('Raw Data'!$A$2:$A$1000<EDATE($A45,1))*'Raw Data'!$L$2:$L$1000*'Raw Data'!$O$2:$O$1000)+SUMIFS('Raw Data'!$M$2:$M$1000,'Raw Data'!$A$2:$A$1000,">="&$A45,'Raw Data'!$A$2:$A$1000,"<"&EDATE($A45,1))*$B$9+SUMIFS('Raw Data'!$N$2:$N$1000,'Raw Data'!$A$2:$A$1000,">="&$A45,'Raw Data'!$A$2:$A$1000,"<"&EDATE($A45,1))*$B$10 -> 868290.09 | Q45: =O45-P45 -> 858947.31 | R45: =IFERROR(Q45/O45,0) -> 0.49729546 | S45: =TEXT(A45,"mmm yyyy") -> Jul 2026 | T45: =$B$5 -> 0.85
...

Sheet Dashboard
B1: FOOD PRODUCTION – EXECUTIVE PERFORMANCE REPORT
B2: ="Reporting period: "&TEXT(MIN('Raw Data'!$A$2:$A$1000),"dd mmm yyyy")&" – "&TEXT(MAX('Raw Data'!$A$2:$A$1000),"dd mmm yyyy")&" | 4 production lines · 8 products · "&TEXT(Calculations!$B$29,"#,##0")&" batches" -> Reporting period: 01 Jul 2026 – 30 Sep 2026 | 4 production lines · 8 products · 368 batches
B4: View ▶ | C4: All | D4: Drop-down filters the executive summary and KPI table (insights, line table and charts cover the whole plant).
B6: EXECUTIVE SUMMARY
B7: ="For "&IF($C$4="All","all lines","the "&$C$4&" line")&", OEE was "&TEXT(D13,"0.0%")&" against a "&TEXT(E13,"0%")&" target ("&IF(D13>=E13,"above","below")&" by "&TEXT(ABS(D13-E13)*100,"0.0")&" pts), with "&CHOOSE(MATCH(MIN(Calculations!$B$79:$B$81),Calculations!$B$79:$B$81,0),"availability","performance","quality")&" the weakest element. "&"Rejects were "&TEXT(D15,"0.0%")&" of output and gross margin was "&TEXT(D16,"0.0%")&" ("&TEXT(Calculations!$B$84,"$#,##0")&" on "&TEXT(Calculations!$B$76,"$#,##0")&" revenue)." -> For all lines, OEE was 81.4% against a 85% target (below by 3.6 pts), with performance the weakest element. Rejects were 2.1% of output and gross margin was 48.6% ($2,483,303 on $5,114,262 revenue).
B11: KEY PERFORMANCE INDICATORS | H11: KEY INSIGHTS (whole plant)
B12: Metric | D12: Actual | E12: Target | F12: Variance | G12: Status | H12: What stands out
B13: OEE | D13: =Calculations!$B$82 -> 0.81429811 | E13: =Calculations!$B$5 -> 0.85 | F13: =(D13-E13)*100 -> -3.5701892 | G13: =IF(D13>=E13,"● On target","● Off target") -> ● Off target | H13: ="▪ Lowest OEE: "&INDEX(Calculations!$A$25:$A$28,MATCH(MIN(Calculations!$N$25:$N$28),Calculations!$N$25:$N$28,0))&" line ("&TEXT(MIN(Calculations!$N$25:$N$28),"0.0%")&")" -> ▪ Lowest OEE: Bakery line (79.6%)
B14: Total cost ($) | D14: =Calculations!$B$77 -> 2630958.8 | E14: – | F14: – | G14: – | H14: ="▪ Weakest OEE element plant-wide: "&INDEX(Calculations!$K$24:$M$24,MATCH(MIN(Calculations!$K$29:$M$29),Calculations!$K$29:$M$29,0))&" ("&TEXT(MIN(Calculations!$K$29:$M$29),"0.0%")&")" -> ▪ Weakest OEE element plant-wide: Performance (90.4%)
B15: Reject rate | D15: =Calculations!$B$83 -> 0.02098356 | E15: =Calculations!$B$6 -> 0.03 | F15: =(D15-E15)*100 -> -0.90164395 | G15: =IF(D15<=E15,"● On target","● Off target") -> ● On target | H15: ="▪ Top downtime cause: "&INDEX(Calculations!$A$51:$A$57,MATCH(MAX(Calculations!$B$51:$B$57),Calculations!$B$51:$B$57,0))&" ("&TEXT(MAX(Calculations!$C$51:$C$57),"0%")&" of lost minutes)" -> ▪ Top downtime cause: Changeover (24% of lost minutes)
B16: Gross margin % | D16: =Calculations!$B$85 -> 0.48556433 | E16: =Calculations!$B$8 -> 0.3 | F16: =(D16-E16)*100 -> 18.556433 | G16: =IF(D16>=E16,"● On target","● Off target") -> ● On target | H16: ="▪ Highest reject rate: "&INDEX(Calculations!$A$25:$A$28,MATCH(MAX(Calculations!$G$25:$G$28),Calculations!$G$25:$G$28,0))&" line ("&TEXT(MAX(Calculations!$G$25:$G$28),"0.0%")&")" -> ▪ Highest reject rate: Frozen line (3.9%)
B17: Micro-test fail rate | D17: =Calculations!$B$88 -> 0.0054347826 | E17: =Calculations!$B$7 -> 0.01 | F17: =(D17-E17)*100 -> -0.45652174 | G17: =IF(D17<=E17,"● On target","● Off target") -> ● On target | H17: ="▪ Most profitable product: "&INDEX(Calculations!$A$33:$A$40,MATCH(MAX(Calculations!$P$33:$P$40),Calculations!$P$33:$P$40,0))&" ("&TEXT(MAX(Calculations!$P$33:$P$40),"0.0%")&" margin)" -> ▪ Most profitable product: Soda (55.7% margin)
B18: Cost per kg (good output) | D18: =Calculations!$B$86 -> 1.6426389 | E18: – | F18: – | G18: – | H18: ="▪ Least profitable product: "&INDEX(Calculations!$A$33:$A$40,MATCH(MIN(Calculations!$P$33:$P$40),Calculations!$P$33:$P$40,0))&" ("&TEXT(MIN(Calculations!$P$33:$P$40),"0.0%")&" margin)" -> ▪ Least profitable product: Cheese (40.3% margin)
B19: Gross margin ($) | D19: =Calculations!$B$84 -> 2483303.2 | E19: – | F19: – | G19: – | H19: ="▪ Rejected product: "&TEXT(Calculations!$E$29,"#,##0")&" kg (≈ "&TEXT(Calculations!$E$29*Calculations!$Z$29,"$#,##0")&" at cost)" -> ▪ Rejected product: 34,329 kg (≈ $56,390 at cost)
B21: PERFORMANCE BY LINE (whole plant)
B22: Line | C22: OEE | D22: vs Target (pp) | E22: Availability | F22: Performance | G22: Quality | H22: Total Cost ($) | I22: Reject % | J22: Margin % | K22: Cost / kg | L22: Micro Fail % | M22: OEE Status
B23: =Calculations!A25 -> Bakery | C23: =Calculations!N25 -> 0.79563381 | D23: =(C23-Calculations!$B$5)*100 -> -5.4366192 | E23: =Calculations!K25 -> 0.90532156 | F23: =Calculations!L25 -> 0.90236214 | G23: =Calculations!M25 -> 0.97393394 | H23: =Calculations!$W$25 -> 522591.24 | I23: =Calculations!G25 -> 0.026066061 | J23: =Calculations!Y25 -> 0.48900737 | K23: =Calculations!Z25 -> 1.9898232 | L23: =Calculations!AB25 -> 0 | M23: =IF(C23>=Calculations!$B$5,"● On target","● Below target") -> ● Below target
B24: =Calculations!A26 -> Dairy | C24: =Calculations!N26 -> 0.8081105 | D24: =(C24-Calculations!$B$5)*100 -> -4.1889499 | E24: =Calculations!K26 -> 0.91474185 | F24: =Calculations!L26 -> 0.90431386 | G24: =Calculations!M26 -> 0.97690653 | H24: =Calculations!$W$26 -> 754544.91 | I24: =Calculations!G26 -> 0.023093468 | J24: =Calculations!Y26 -> 0.44558471 | K24: =Calculations!Z26 -> 2.6495806 | L24: =Calculations!AB26 -> 0.010869565 | M24: =IF(C24>=Calculations!$B$5,"● On target","● Below target") -> ● Below target
B25: =Calculations!A27 -> Beverage | C25: =Calculations!N27 -> 0.82413947 | D25: =(C25-Calculations!$B$5)*100 -> -2.586053 | E25: =Calculations!K27 -> 0.9238904 | F25: =Calculations!L27 -> 0.90408809 | G25: =Calculations!M27 -> 0.98666452 | H25: =Calculations!$W$27 -> 583671.72 | I25: =Calculations!G27 -> 0.013335484 | J25: =Calculations!Y27 -> 0.52741374 | K25: =Calculations!Z27 -> 0.71198059 | L25: =Calculations!AB27 -> 0.010869565 | M25: =IF(C25>=Calculations!$B$5,"● On target","● Below target") -> ● Below target
B26: =Calculations!A28 -> Frozen | C26: =Calculations!N28 -> 0.81479515 | D26: =(C26-Calculations!$B$5)*100 -> -3.5204852 | E26: =Calculations!K28 -> 0.93600543 | F26: =Calculations!L28 -> 0.90572826 | G26: =Calculations!M28 -> 0.9611079 | H26: =Calculations!$W$28 -> 770150.93 | I26: =Calculations!G28 -> 0.0388921 | J26: =Calculations!Y28 -> 0.48503178 | K26: =Calculations!Z28 -> 3.2846599 | L26: =Calculations!AB28 -> 0 | M26: =IF(C26>=Calculations!$B$5,"● On target","● Below target") -> ● Below target
B27: =Calculations!A29 -> Total | C27: =Calculations!N29 -> 0.81429811 | D27: =(C27-Calculations!$B$5)*100 -> -3.5701892 | E27: =Calculations!K29 -> 0.91998981 | F27: =Calculations!L29 -> 0.90408742 | G27: =Calculations!M29 -> 0.97901644 | H27: =Calculations!$W$29 -> 2630958.8 | I27: =Calculations!G29 -> 0.02098356 | J27: =Calculations!Y29 -> 0.48556433 | K27: =Calculations!Z29 -> 1.6426389 | L27: =Calculations!AB29 -> 0.0054347826 | M27: =IF(C27>=Calculations!$B$5,"● On target","● Below target") -> ● Below target
B29: TRENDS & DRIVERS
B62: RECOMMENDED ACTIONS (auto-generated from the data)
B63: ="1. Run a root-cause review of "&LOWER(INDEX(Calculations!$A$51:$A$57,MATCH(MAX(Calculations!$B$51:$B$57),Calculations!$B$51:$B$57,0)))&" – the largest source of lost time ("&TEXT(MAX(Calculations!$C$51:$C$57),"0%")&" of downtime minutes)." -> 1. Run a root-cause review of changeover – the largest source of lost time (24% of downtime minutes).
B64: ="2. Investigate quality losses on the "&INDEX(Calculations!$A$25:$A$28,MATCH(MAX(Calculations!$G$25:$G$28),Calculations!$G$25:$G$28,0))&" line: reject rate "&TEXT(MAX(Calculations!$G$25:$G$28),"0.0%")&" vs a "&TEXT(Calculations!$B$6,"0.0%")&" limit ("&TEXT(Calculations!$E$29,"#,##0")&" kg rejected plant-wide)." -> 2. Investigate quality losses on the Frozen line: reject rate 3.9% vs a 3.0% limit (34,329 kg rejected plant-wide).
B65: ="3. Close the "&LOWER(INDEX(Calculations!$K$24:$M$24,MATCH(MIN(Calculations!$K$29:$M$29),Calculations!$K$29:$M$29,0)))&" gap, starting with "&INDEX(Calculations!$A$25:$A$28,MATCH(MIN(Calculations!$N$25:$N$28),Calculations!$N$25:$N$28,0))&" (OEE "&TEXT(MIN(Calculations!$N$25:$N$28),"0.0%")&" vs "&TEXT(Calculations!$B$5,"0%")&" target)." -> 3. Close the performance gap, starting with Bakery (OEE 79.6% vs 85% target).
B67: Notes: sample data is synthetic. Targets, prices and energy/labor rates are assumptions – edit the blue/yellow cells in the Calculations tab. KPIs: OEE = Availability × Performance × Quality.
